<?xml version="1.0"?>
<robot name="DobBot_hrik">

  <!-- Base Link (Car body) -->
  <link name="base_link">
    <visual>
      <geometry>
        <box size="0.6 0.4 0.2"/>
      </geometry>
      <material name="red">
        <color rgba="1 0 0 1"/>
      </material>
    </visual>
  </link>

  <!-- Spherical Wheels -->
  
  <!-- Front Left Sphere -->
  <link name="front_left_wheel">
    <visual>
      <geometry>
        <sphere radius="0.1"/>
      </geometry>
      <material name="blue">
        <color rgba="0 0 1 1"/>
      </material>
    </visual>
  </link>

  <!-- Front Right Sphere -->
  <link name="front_right_wheel">
    <visual>
      <geometry>
        <sphere radius="0.1"/>
      </geometry>
      <material name="blue">
        <color rgba="0 0 1 1"/>
      </material>
    </visual>
  </link>

  <!-- Rear Left Sphere -->
  <link name="rear_left_wheel">
    <visual>
      <geometry>
        <sphere radius="0.1"/>
      </geometry>
      <material name="blue">
        <color rgba="0 0 1 1"/>
      </material>
    </visual>
  </link>

  <!-- Rear Right Sphere -->
  <link name="rear_right_wheel">
    <visual>
      <geometry>
        <sphere radius="0.1"/>
      </geometry>
      <material name="blue">
        <color rgba="0 0 1 1"/>
      </material>
    </visual>
  </link>


  <joint name="front_left_wheel_joint" type="revolute">
    <parent link="base_link"/>
    <child link="front_left_wheel"/>
    <origin xyz="-0.25 0.2 -0.1" rpy="0 0 0"/>
    <axis xyz="0 1 0"/>
    <limit lower="-3.14159" upper="3.14159" effort="10" velocity="0.005"/>
  </joint>

  <joint name="front_right_wheel_joint" type="revolute">
    <parent link="base_link"/>
    <child link="front_right_wheel"/>
    <origin xyz="0.25 0.2 -0.1" rpy="0 0 0"/>
    <axis xyz="0 1 0"/>
    <limit lower="-3.14159" upper="3.14159" effort="10" velocity="0.005"/>
  </joint>

  <joint name="rear_left_wheel_joint" type="revolute">
    <parent link="base_link"/>
    <child link="rear_left_wheel"/>
    <origin xyz="-0.25 -0.2 -0.1" rpy="0 0 0"/>
    <axis xyz="0 1 0"/>
    <limit lower="-3.14159" upper="3.14159" effort="10" velocity="0.005"/>
  </joint>

  <joint name="rear_right_wheel_joint" type="revolute">
    <parent link="base_link"/>
    <child link="rear_right_wheel"/>
    <origin xyz="0.25 -0.2 -0.1" rpy="0 0 0"/>
    <axis xyz="0 1 0"/>
    <limit lower="-3.14159" upper="3.14159" effort="10" velocity="0.005"/>
  </joint>

</robot>
